2022-05-27 17:11:09 WARNING (SyncWorker_0) [homeassistant.loader] We found a custom integration webrtc which has not been tested by Home Assistant. This component might cause stability problems, be sure to disable it if you experience issues with Home Assistant
2022-05-27 17:11:09 WARNING (SyncWorker_1) [homeassistant.loader] We found a custom integration tapo_control which has not been tested by Home Assistant. This component might cause stability problems, be sure to disable it if you experience issues with Home Assistant
2022-05-27 17:23:19 WARNING (MainThread) [homeassistant.helpers.service] Unable to find referenced entities camera.bedroom_hd or it is/they are currently not available
2022-05-27 17:23:20 WARNING (MainThread) [homeassistant.helpers.service] Unable to find referenced entities camera.bedroom_hd or it is/they are currently not available
2022-05-27 17:29:22 ERROR (MainThread) [homeassistant.components.websocket_api.http.connection] [140345660396256] Error: -64301 Response:{"error_code": -64301}
Traceback (most recent call last):
  File "/usr/src/homeassistant/homeassistant/components/websocket_api/commands.py", line 193, in handle_call_service
    await hass.services.async_call(
  File "/usr/src/homeassistant/homeassistant/core.py", line 1673, in async_call
    task.result()
  File "/usr/src/homeassistant/homeassistant/core.py", line 1710, in _execute_service
    await cast(Callable[[ServiceCall], Awaitable[None]], handler.job.target)(
  File "/usr/src/homeassistant/homeassistant/helpers/entity_platform.py", line 697, in handle_service
    await service.entity_service_call(
  File "/usr/src/homeassistant/homeassistant/helpers/service.py", line 690, in entity_service_call
    future.result()  # pop exception if have
  File "/usr/src/homeassistant/homeassistant/helpers/entity.py", line 964, in async_request_call
    await coro
  File "/usr/src/homeassistant/homeassistant/helpers/service.py", line 728, in _handle_entity_call
    await result
  File "/config/custom_components/tapo_control/camera.py", line 357, in ptz
    await self.hass.async_add_executor_job(
  File "/usr/local/lib/python3.9/concurrent/futures/thread.py", line 58, in run
    result = self.fn(*self.args, **self.kwargs)
  File "/usr/local/lib/python3.9/site-packages/pytapo/__init__.py", line 280, in moveMotor
    return self.performRequest(
  File "/usr/local/lib/python3.9/site-packages/pytapo/__init__.py", line 113, in performRequest
    raise Exception(
Exception: Error: -64301 Response:{"error_code": -64301}
2022-05-27 17:29:26 ERROR (MainThread) [homeassistant.components.websocket_api.http.connection] [140345660396256] Error: -64301 Response:{"error_code": -64301}
Traceback (most recent call last):
  File "/usr/src/homeassistant/homeassistant/components/websocket_api/commands.py", line 193, in handle_call_service
    await hass.services.async_call(
  File "/usr/src/homeassistant/homeassistant/core.py", line 1673, in async_call
    task.result()
  File "/usr/src/homeassistant/homeassistant/core.py", line 1710, in _execute_service
    await cast(Callable[[ServiceCall], Awaitable[None]], handler.job.target)(
  File "/usr/src/homeassistant/homeassistant/helpers/entity_platform.py", line 697, in handle_service
    await service.entity_service_call(
  File "/usr/src/homeassistant/homeassistant/helpers/service.py", line 690, in entity_service_call
    future.result()  # pop exception if have
  File "/usr/src/homeassistant/homeassistant/helpers/entity.py", line 964, in async_request_call
    await coro
  File "/usr/src/homeassistant/homeassistant/helpers/service.py", line 728, in _handle_entity_call
    await result
  File "/config/custom_components/tapo_control/camera.py", line 357, in ptz
    await self.hass.async_add_executor_job(
  File "/usr/local/lib/python3.9/concurrent/futures/thread.py", line 58, in run
    result = self.fn(*self.args, **self.kwargs)
  File "/usr/local/lib/python3.9/site-packages/pytapo/__init__.py", line 280, in moveMotor
    return self.performRequest(
  File "/usr/local/lib/python3.9/site-packages/pytapo/__init__.py", line 113, in performRequest
    raise Exception(
Exception: Error: -64301 Response:{"error_code": -64301}
2022-05-27 17:29:38 ERROR (MainThread) [homeassistant.components.websocket_api.http.connection] [140345660396256] Error: -64301 Response:{"error_code": -64301}
Traceback (most recent call last):
  File "/usr/src/homeassistant/homeassistant/components/websocket_api/commands.py", line 193, in handle_call_service
    await hass.services.async_call(
  File "/usr/src/homeassistant/homeassistant/core.py", line 1673, in async_call
    task.result()
  File "/usr/src/homeassistant/homeassistant/core.py", line 1710, in _execute_service
    await cast(Callable[[ServiceCall], Awaitable[None]], handler.job.target)(
  File "/usr/src/homeassistant/homeassistant/helpers/entity_platform.py", line 697, in handle_service
    await service.entity_service_call(
  File "/usr/src/homeassistant/homeassistant/helpers/service.py", line 690, in entity_service_call
    future.result()  # pop exception if have
  File "/usr/src/homeassistant/homeassistant/helpers/entity.py", line 964, in async_request_call
    await coro
  File "/usr/src/homeassistant/homeassistant/helpers/service.py", line 728, in _handle_entity_call
    await result
  File "/config/custom_components/tapo_control/camera.py", line 361, in ptz
    await self.hass.async_add_executor_job(
  File "/usr/local/lib/python3.9/concurrent/futures/thread.py", line 58, in run
    result = self.fn(*self.args, **self.kwargs)
  File "/usr/local/lib/python3.9/site-packages/pytapo/__init__.py", line 280, in moveMotor
    return self.performRequest(
  File "/usr/local/lib/python3.9/site-packages/pytapo/__init__.py", line 113, in performRequest
    raise Exception(
Exception: Error: -64301 Response:{"error_code": -64301}
